<?xml version="1.0" ?>
<sdf version="1.8">
  <model name="ackermann_car">

    <link name="chassis">
      <inertial>
        <mass>1.0</mass>
        <inertia>
          <ixx>0.005</ixx>
          <iyy>0.007</iyy>
          <izz>0.011</izz>
        </inertia>
      </inertial>

      <!-- Front section of chassis -->
      <collision name="chassis_front_collision">
        <pose>0.105 0 0 0 0 0</pose>
        <geometry>
          <box>
            <size>0.15 0.06 0.07</size>
          </box>
        </geometry>
      </collision>
      <visual name="chassis_front_visual">
        <pose>0.105 0 0 0 0 0</pose>
        <geometry>
          <box>
            <size>0.15 0.06 0.07</size>
          </box>
        </geometry>
        <material>
          <ambient>1 0 0 1</ambient>
          <diffuse>1 0 0 1</diffuse>
          <specular>0.1 0.1 0.1 1</specular>
        </material>
      </visual>

      <!-- Middle section of chassis -->
      <collision name="chassis_middle_collision">
        <pose>0 0 0 0 0 0</pose>
        <geometry>
          <box>
            <size>0.06 0.14 0.07</size>
          </box>
        </geometry>
      </collision>
      <visual name="chassis_middle_visual">
        <pose>0 0 0 0 0 0</pose>
        <geometry>
          <box>
            <size>0.06 0.14 0.07</size>
          </box>
        </geometry>
        <material>
          <ambient>1 0 0 1</ambient>
          <diffuse>1 0 0 1</diffuse>
          <specular>0.1 0.1 0.1 1</specular>
        </material>
      </visual>

      <!-- Rear section of chassis -->
      <collision name="chassis_rear_collision">
        <pose>-0.105 0 0 0 0 0</pose>
        <geometry>
          <box>
            <size>0.15 0.20 0.07</size>
          </box>
        </geometry>
      </collision>
      <visual name="chassis_rear_visual">
        <pose>-0.105 0 0 0 0 0</pose>
        <geometry>
          <box>
            <size>0.15 0.12 0.07</size>
          </box>
        </geometry>
        <material>
          <ambient>1 0 0 1</ambient>
          <diffuse>1 0 0 1</diffuse>
          <specular>0.1 0.1 0.1 1</specular>
        </material>
      </visual>

      <!-- RGB Camera Sensor -->
      <sensor name="camera" type="camera">
        <pose>0 0 0.12 0 0 0</pose>
        <camera>
          <horizontal_fov>1.047</horizontal_fov>
          <image>
            <width>320</width>
            <height>240</height>
          </image>
          <clip>
            <near>0.1</near>
            <far>100</far>
          </clip>
        </camera>
        <always_on>1</always_on>
        <update_rate>30</update_rate>
        <visualize>true</visualize>
      </sensor>


      <!-- IMU Sensor -->
      <sensor name="imu" type="imu">
        <pose>0 0 0.1 0 0 0</pose>
        <update_rate>100</update_rate>
        <imu>
          <angular_velocity>
            <x>true</x>
            <y>true</y>
            <z>true</z>
          </angular_velocity>
          <linear_acceleration>
            <x>true</x>
            <y>true</y>
            <z>true</z>
          </linear_acceleration>
        </imu>
      </sensor>

      <!-- GPS Sensor -->
      <sensor name="gps" type="gps">
        <pose>0 0 0.1 0 0 0</pose>
        <gps>
          <position_sensing>
            <horizontal>true</horizontal>
            <vertical>true</vertical>
          </position_sensing>
          <velocity_sensing>
            <horizontal>true</horizontal>
            <vertical>true</vertical>
          </velocity_sensing>
        </gps>
      </sensor>

      <!-- 2D Lidar Sensor -->
      <sensor name="lidar" type="gpu_lidar">
        <pose relative_to='lidar_frame'>0 0 0 0 0 0</pose>
        <visualize>true</visualize>
        <always_on>1</always_on>
        <update_rate>10</update_rate>
        <ray>
          <scan>
            <horizontal>
              <samples>640</samples>
              <resolution>1</resolution>
              <min_angle>-1.396263</min_angle>
              <max_angle>1.396263</max_angle>
            </horizontal>
            <vertical>
              <samples>1</samples>
              <resolution>0.01</resolution>
              <min_angle>0</min_angle>
              <max_angle>0</max_angle>
            </vertical>
          </scan>
          <range>
            <min>0.08</min>
            <max>12.0</max>
            <resolution>0.01</resolution>
          </range>
        </ray>
      </sensor>
    </link>

    <frame name="lidar_frame" attached_to='chassis'>
      <pose>0.0 0 0.1 0 0 0</pose>
    </frame>

    <!-- Steering links -->
    <link name="front_left_wheel_steering_link">
      <pose>0.11 0.06 -0.03 0 0 0</pose>
        <inertial>
          <mass>0.001</mass>
          <inertia>
            <ixx>0.001</ixx>
            <iyy>0.001</iyy>
            <izz>0.001</izz>
          </inertia>
        </inertial>
        <visual name="steering_link_visual">
          <pose>0 0 0 0 0 0</pose>
          <geometry>
            <cylinder>
              <length>0.03</length>
              <radius>0.01</radius>
            </cylinder>
          </geometry>
          <material>
            <ambient>1 1 1</ambient>
            <diffuse>1 1 1</diffuse>
          </material>
        </visual>
    </link>

    <link name="front_right_wheel_steering_link">
      <pose>0.11 -0.06 -0.03 0 0 0</pose>
        <inertial>
          <mass>0.001</mass>
          <inertia>
            <ixx>0.001</ixx>
            <iyy>0.001</iyy>
            <izz>0.001</izz>
          </inertia>
        </inertial>
        <visual name="steering_link_visual">
          <pose>0 0 0 0 0 0</pose>
          <geometry>
            <cylinder>
              <length>0.03</length>
              <radius>0.01</radius>
            </cylinder>
          </geometry>
          <material>
            <ambient>1 1 1</ambient>
            <diffuse>1 1 1</diffuse>
          </material>
        </visual>
    </link>

    <!-- Front Left Wheel -->
    <link name="front_left_wheel">
      <pose>0.11 0.12 -0.03 -1.5707 0 0</pose>
      <inertial>
        <mass>0.2</mass>
        <inertia>
          <ixx>0.0001</ixx>
          <iyy>0.0001</iyy>
          <izz>0.0001</izz>
        </inertia>
      </inertial>
      <collision name="front_left_wheel_collision">
        <geometry>
          <cylinder>
            <radius>0.07</radius>
            <length>0.10</length>
          </cylinder>
        </geometry>
      </collision>
      <visual name="front_left_wheel_visual">
        <geometry>
          <cylinder>
            <radius>0.07</radius>
            <length>0.10</length>
          </cylinder>
        </geometry>
        <material>
          <ambient>0 0 0 1</ambient>
          <diffuse>0 0 0 1</diffuse>
        </material>
      </visual>
    </link>

    <!-- Front Right Wheel -->
    <link name="front_right_wheel">
      <pose>0.11 -0.12 -0.03 -1.5707 0 0</pose>
      <inertial>
        <mass>0.2</mass>
        <inertia>
          <ixx>0.0001</ixx>
          <iyy>0.0001</iyy>
          <izz>0.0001</izz>
        </inertia>
      </inertial>
      <collision name="front_right_wheel_collision">
        <geometry>
          <cylinder>
            <radius>0.07</radius>
            <length>0.10</length>
          </cylinder>
        </geometry>
      </collision>
      <visual name="front_right_wheel_visual">
        <geometry>
          <cylinder>
            <radius>0.07</radius>
            <length>0.10</length>
          </cylinder>
        </geometry>
        <material>
          <ambient>0 0 0 1</ambient>
          <diffuse>0 0 0 1</diffuse>
        </material>
      </visual>
    </link>

    <!-- Rear Left Wheel -->
    <link name="rear_left_wheel">
      <pose>-0.11 0.12 -0.03 -1.5707 0 0</pose>
      <inertial>
        <mass>0.2</mass>
        <inertia>
          <ixx>0.0001</ixx>
          <iyy>0.0001</iyy>
          <izz>0.0001</izz>
        </inertia>
      </inertial>
      <collision name="rear_left_wheel_collision">
        <geometry>
          <cylinder>
            <radius>0.07</radius>
            <length>0.10</length>
          </cylinder>
        </geometry>
      </collision>
      <visual name="rear_left_wheel_visual">
        <geometry>
          <cylinder>
            <radius>0.07</radius>
            <length>0.10</length>
          </cylinder>
        </geometry>
        <material>
          <ambient>0 0 0 1</ambient>
          <diffuse>0 0 0 1</diffuse>
        </material>
      </visual>
    </link>

    <!-- Rear Right Wheel -->
    <link name="rear_right_wheel">
      <pose>-0.11 -0.12 -0.03 -1.5707 0 0</pose>
      <inertial>
        <mass>0.2</mass>
        <inertia>
          <ixx>0.0001</ixx>
          <iyy>0.0001</iyy>
          <izz>0.0001</izz>
        </inertia>
      </inertial>
      <collision name="rear_right_wheel_collision">
        <geometry>
          <cylinder>
            <radius>0.07</radius>
            <length>0.10</length>
          </cylinder>
        </geometry>
      </collision>
      <visual name="rear_right_wheel_visual">
        <geometry>
          <cylinder>
            <radius>0.07</radius>
            <length>0.10</length>
          </cylinder>
        </geometry>
        <material>
          <ambient>0 0 0 1</ambient>
          <diffuse>0 0 0 1</diffuse>
        </material>
      </visual>
    </link>

    <joint name="front_left_wheel_steering_joint" type="revolute">
      <parent>chassis</parent>
      <child>front_left_wheel_steering_link</child>
      <axis>
        <xyz>0 0 1</xyz>
        <limit>
          <lower>-0.5</lower>
          <upper>0.5</upper>
          <effort>25</effort>
        </limit>
      </axis>
    </joint>

    <joint name="front_right_wheel_steering_joint" type="revolute">
      <parent>chassis</parent>
      <child>front_right_wheel_steering_link</child>
      <axis>
        <xyz>0 0 1</xyz>
        <limit>
          <lower>-0.5</lower>
          <upper>0.5</upper>
          <effort>25</effort>
        </limit>
      </axis>
    </joint>

    <joint name="front_left_wheel_joint" type="revolute">
      <parent>front_left_wheel_steering_link</parent>
      <child>front_left_wheel</child>
      <axis>
        <xyz>0 0 1</xyz>
        <limit>
          <lower>-1.79769e+308</lower>
          <upper>1.79769e+308</upper>
        </limit>
      </axis>
    </joint>

    <joint name="front_right_wheel_joint" type="revolute">
      <parent>front_right_wheel_steering_link</parent>
      <child>front_right_wheel</child>
      <axis>
        <xyz>0 0 1</xyz>
        <limit>
          <lower>-1.79769e+308</lower>
          <upper>1.79769e+308</upper>
        </limit>
      </axis>
    </joint>

    <joint name="rear_left_wheel_joint" type="revolute">
      <parent>chassis</parent>
      <child>rear_left_wheel</child>
      <axis>
        <xyz>0 0 1</xyz>
        <limit>
          <lower>-1.79769e+308</lower>
          <upper>1.79769e+308</upper>
        </limit>
      </axis>
    </joint>

    <joint name="rear_right_wheel_joint" type="revolute">
      <parent>chassis</parent>
      <child>rear_right_wheel</child>
      <axis>
        <xyz>0 0 1</xyz>
        <limit>
          <lower>-1.79769e+308</lower>
          <upper>1.79769e+308</upper>
        </limit>
      </axis>
    </joint>

    <!-- Ackermann Steering Plugin -->
    <plugin
      filename="gz-sim-ackermann-steering-system"
      name="gz::sim::systems::AckermannSteering">
      <left_joint>front_left_wheel_joint</left_joint>
      <left_joint>rear_left_wheel_joint</left_joint>
      <right_joint>front_right_wheel_joint</right_joint>
      <right_joint>rear_right_wheel_joint</right_joint>
      <left_steering_joint>front_left_wheel_steering_joint</left_steering_joint>
      <right_steering_joint>front_right_wheel_steering_joint</right_steering_joint>
      <wheel_base>0.20</wheel_base>
      <wheel_separation>0.24</wheel_separation>
      <kingpin_width>0.05</kingpin_width>
      <steering_limit>0.5</steering_limit>
      <wheel_radius>0.07</wheel_radius>
      <odom_publish_frequency>50</odom_publish_frequency>
      <max_speed>2.0</max_speed>
      <min_speed>-2.0</min_speed>
      <max_acceleration>2.0</max_acceleration>
      <max_steering_rate>1.0</max_steering_rate>
    </plugin>
  </model>
</sdf>
